{
  try {
    c.close();
  }
 catch (  Exception e) {
    log.debug("exception on close of: " + c,e);
  }
}
